Ошибка 1 -  Сессии и авторизация.

После перемещения корабля на одну клетку влева, и быстрого выхода и входа с той же session id меняется место, где находится корабль

Противоречит: Состояние пользовательских данных должно сохраняться после выхода из
приложения. При последующем входе пользователь окажется в той же позиции
(см. 2) 

Тест - test_1


Ошибка 2 -  Сессии и авторизация.

После логаута и логина могут меняться события в море, даже когда корабль остаётся на одном месте.

Противоречит: Состояние пользовательских данных должно сохраняться после выхода из
приложения. 

Тест - test_3


Ошибка 3 - Описание модели и режима перемещения

При перемещении корабля можно нажать несколько раз на срелку влево и тогда корабль попавдёт за пределы полей [-20;20]

Противоречит: Поле модели
представляет собой одномерное пространство, для которого активные объекты
(не являющиеся морем) расположены в пределах координат [-20, 20].

Тест - test_2

Ошибка 4 - Описание модели и режима перемещения

При нажатии клавиши стрелок несколько раз корабль производит движение на соответсвующее количество полей при этом тратя 2 секунды, указанные как перемещение на одно поле

Противоречит: При этом имеется ограничение на время
перемещения на одну клетку которое должно составлять не менее 2 секунд.

Тест - test_4

Ошибка 5 -  Описание режима торговли

При попытке продажи большего количества товара чем есть на корабле происходит изменения количества денег в порту, хотя оно происходить не должно.

Противоречит: Если операция не допустима, то изменений не происходит и обновление
не производится.

Тест - test_5


результат тестов:

python -u "g:\C\H8\test.py"
F0CRQlO8GivERvV0tLI
Море [-30]
FPvKLNcJulTHjYJepPi
New text = Безмятежное синее море
FjkxHqiW6VFWcjSXRrJ
FujPgr3j7S9pA7WCIGH
!!!! 281824.30
F.
======================================================================
FAIL: test_1 (__main__.PythonOrgSearch.test_1)
----------------------------------------------------------------------
Traceback (most recent call last):
  File "g:\C\H8\test.py", line 45, in test_1
    self.assertEqual(elem_text, saved_elem_text)
AssertionError: 'Когда появился этот мир, одним их первых [236 chars]ПОРТ' != 'Безмятежное синее море\nСобытие:\nНа судн[140 chars] нет'
- Когда появился этот мир, одним их первых поселений стал этот город. Расположенный в самой безопасной части мира, сегодня он приютил большую часть законопослушного населения.
+ Безмятежное синее море
  Событие:
+ На судне поднялась суматоха - один из матросов пропал. После опроса команды, вы решили что он вывалился за борт, но когда это произошло? Свиделетей нет- Добро пожаловать! Для перемещения используйте стрелки под изображением!
- Действия:
- ЗАЙТИ В ПОРТ

======================================================================
FAIL: test_2 (__main__.PythonOrgSearch.test_2)
----------------------------------------------------------------------
Traceback (most recent call last):
  File "g:\C\H8\test.py", line 66, in test_2
    self.assertNotEqual(elem_text, 'Море [-30]')
AssertionError: 'Море [-30]' == 'Море [-30]'

======================================================================
FAIL: test_3 (__main__.PythonOrgSearch.test_3)
----------------------------------------------------------------------
Traceback (most recent call last):
  File "g:\C\H8\test.py", line 101, in test_3
    self.assertEqual(elem_text, saved_elem_text)
AssertionError: 'Безм[13 chars] море' != 'Безм[13 chars] море\nСобытие:\nНа горизонте маячит корабль. [93 chars]ена.'
- Безмятежное синее море
+ Безмятежное синее море
Событие:
На горизонте маячит корабль. Впередисмотрящий утверждает что на флаге нарисован череп и соломенная шляпа. Команда встревожена.


======================================================================
FAIL: test_4 (__main__.PythonOrgSearch.test_4)
----------------------------------------------------------------------
Traceback (most recent call last):
  File "g:\C\H8\test.py", line 123, in test_4
    self.assertNotEqual(elem_text[-5:], '[-19]')
AssertionError: '[-19]' == '[-19]'

======================================================================
FAIL: test_5 (__main__.PythonOrgSearch.test_5)
----------------------------------------------------------------------
Traceback (most recent call last):
  File "g:\C\H8\test.py", line 152, in test_5
    self.assertEqual(saved_elem_text, elem_text)
AssertionError: '281824.30' != '298038.30'
- 281824.30
+ 298038.30


----------------------------------------------------------------------
Ran 6 tests in 57.236s

FAILED (failures=5)